Workbook
Name List: 'Apthera IOL Exper - Print Old -'!$G$8:$G$27
Name List: 'Envy Experience Tracker '!$AD$7:$AD$37
Name List: 'Envy Experience - Input'!$G$8:$G$27
Name NumVal: Parameters!$J$2
Name PatientIdentifier: OFFSET(#REF!,0,0,COUNTA(#REF!),1)

Sheet Envy Experience - Input
Y2: Include Y/N This provides opportunity to remove outliers that would affect results, i.e. post refractive, corneal/retinal pathology or questionable outcomes noted when reviewing data
A6: Column1 | E6: IOL Power | F6: Lens Type | G6: Patient Identifier | H6: Est. Date Of Service | I6: Eye (OD/OS) | J6: SEQ Target | K6: Pre Op Flat K | L6: Pre-Op Steep K | M6: Flat & Steep K Diff | N6: BCDVA | O6: UCDVA | P6: UCIVA | Q6: UCNVA | R6: SEQ Outcome | S6: Refractive Residual Cylinder | T6: Corneal Residual Cylinder | U6: Include (Y/N) | V6: SEQ Diff | W6: Column1 | X6: Column12 | Y6: Definitions:
A7: =Data[[#This Row],[Patient Identifier]]&Data[[#This Row],[Eye (OD/OS)]] -> 99999OD | D7: EX. | E7: 22.00/1.50 | F7: enVista | G7: 99999 | H7: 43831 | I7: OD | J7: -0.5 | K7: 44.5 | L7: 45 | M7: =ABS(Data[[#This Row],[Pre-Op Steep K]]-Data[[#This Row],[Pre Op Flat K]]) -> 0.5 | N7: 20/20 | O7: 20/25 | P7: 20/20 | Q7: J3 | R7: -0.25 | S7: 0.05 | U7: No | V7: =IF(X7=-1,(Data[[#This Row],[SEQ Target]]-Data[[#This Row],[SEQ Outcome]])*X7,ABS((Data[[#This Row],[SEQ Target]]-Data[[#This Row],[SEQ Outcome]])*X7)) -> 0.25 | W7: =IF(AND(Data[[#This Row],[Patient Identifier]]<>"Enter ID",Data[[#This Row],[Include (Y/N)]]="Yes"),1,0) -> 0 | X7: =IF(Data[[#This Row],[SEQ Outcome]]<Data[[#This Row],[SEQ Target]],-1,1) -> 1 | Y7: SEQ Target - Surgeon’s expected predict/target
A8: =Data[[#This Row],[Patient Identifier]]&Data[[#This Row],[Eye (OD/OS)]] | M8: =ABS(Data[[#This Row],[Pre-Op Steep K]]-Data[[#This Row],[Pre Op Flat K]]) -> 0 | V8: =IF(X8=-1,(Data[[#This Row],[SEQ Target]]-Data[[#This Row],[SEQ Outcome]])*X8,ABS((Data[[#This Row],[SEQ Target]]-Data[[#This Row],[SEQ Outcome]])*X8)) -> 0 | W8: =IF(AND(Data[[#This Row],[Patient Identifier]]<>"Enter ID",Data[[#This Row],[Include (Y/N)]]="Yes"),1,0) -> 0 | X8: =IF(Data[[#This Row],[SEQ Outcome]]<Data[[#This Row],[SEQ Target]],-1,1) -> 1 | Y8: SEQ Outcome - Patient’s spherical equivalent refractive outcome
A9: =Data[[#This Row],[Patient Identifier]]&Data[[#This Row],[Eye (OD/OS)]] | M9: =ABS(Data[[#This Row],[Pre-Op Steep K]]-Data[[#This Row],[Pre Op Flat K]]) -> 0 | V9: =IF(X9=-1,(Data[[#This Row],[SEQ Target]]-Data[[#This Row],[SEQ Outcome]])*X9,ABS((Data[[#This Row],[SEQ Target]]-Data[[#This Row],[SEQ Outcome]])*X9)) -> 0 | W9: =IF(AND(Data[[#This Row],[Patient Identifier]]<>"Enter ID",Data[[#This Row],[Include (Y/N)]]="Yes"),1,0) -> 0 | X9: =IF(Data[[#This Row],[SEQ Outcome]]<Data[[#This Row],[SEQ Target]],-1,1) -> 1 | Y9: SEQ Difference - Difference between expected target and refractive outcome
A10: =Data[[#This Row],[Patient Identifier]]&Data[[#This Row],[Eye (OD/OS)]] | M10: =ABS(Data[[#This Row],[Pre-Op Steep K]]-Data[[#This Row],[Pre Op Flat K]]) -> 0 | V10: =IF(X10=-1,(Data[[#This Row],[SEQ Target]]-Data[[#This Row],[SEQ Outcome]])*X10,ABS((Data[[#This Row],[SEQ Target]]-Data[[#This Row],[SEQ Outcome]])*X10)) -> 0 | W10: =IF(AND(Data[[#This Row],[Patient Identifier]]<>"Enter ID",Data[[#This Row],[Include (Y/N)]]="Yes"),1,0) -> 0 | X10: =IF(Data[[#This Row],[SEQ Outcome]]<Data[[#This Row],[SEQ Target]],-1,1) -> 1 | Y10: OD: Right Eye
A11: =Data[[#This Row],[Patient Identifier]]&Data[[#This Row],[Eye (OD/OS)]] | M11: =ABS(Data[[#This Row],[Pre-Op Steep K]]-Data[[#This Row],[Pre Op Flat K]]) -> 0 | V11: =IF(X11=-1,(Data[[#This Row],[SEQ Target]]-Data[[#This Row],[SEQ Outcome]])*X11,ABS((Data[[#This Row],[SEQ Target]]-Data[[#This Row],[SEQ Outcome]])*X11)) -> 0 | W11: =IF(AND(Data[[#This Row],[Patient Identifier]]<>"Enter ID",Data[[#This Row],[Include (Y/N)]]="Yes"),1,0) -> 0 | X11: =IF(Data[[#This Row],[SEQ Outcome]]<Data[[#This Row],[SEQ Target]],-1,1) -> 1 | Y11: OS: Left Eye
A12: =Data[[#This Row],[Patient Identifier]]&Data[[#This Row],[Eye (OD/OS)]] | M12: =ABS(Data[[#This Row],[Pre-Op Steep K]]-Data[[#This Row],[Pre Op Flat K]]) -> 0 | V12: =IF(X12=-1,(Data[[#This Row],[SEQ Target]]-Data[[#This Row],[SEQ Outcome]])*X12,ABS((Data[[#This Row],[SEQ Target]]-Data[[#This Row],[SEQ Outcome]])*X12)) -> 0 | W12: =IF(AND(Data[[#This Row],[Patient Identifier]]<>"Enter ID",Data[[#This Row],[Include (Y/N)]]="Yes"),1,0) -> 0 | X12: =IF(Data[[#This Row],[SEQ Outcome]]<Data[[#This Row],[SEQ Target]],-1,1) -> 1 | Y12: OU: Both Eyes
A13: =Data[[#This Row],[Patient Identifier]]&Data[[#This Row],[Eye (OD/OS)]] | M13: =ABS(Data[[#This Row],[Pre-Op Steep K]]-Data[[#This Row],[Pre Op Flat K]]) -> 0 | V13: =IF(X13=-1,(Data[[#This Row],[SEQ Target]]-Data[[#This Row],[SEQ Outcome]])*X13,ABS((Data[[#This Row],[SEQ Target]]-Data[[#This Row],[SEQ Outcome]])*X13)) -> 0 | W13: =IF(AND(Data[[#This Row],[Patient Identifier]]<>"Enter ID",Data[[#This Row],[Include (Y/N)]]="Yes"),1,0) -> 0 | X13: =IF(Data[[#This Row],[SEQ Outcome]]<Data[[#This Row],[SEQ Target]],-1,1) -> 1 | Y13: UCDVA: Uncorrected visual acuity
A14: =Data[[#This Row],[Patient Identifier]]&Data[[#This Row],[Eye (OD/OS)]] | M14: =ABS(Data[[#This Row],[Pre-Op Steep K]]-Data[[#This Row],[Pre Op Flat K]]) -> 0 | V14: =IF(X14=-1,(Data[[#This Row],[SEQ Target]]-Data[[#This Row],[SEQ Outcome]])*X14,ABS((Data[[#This Row],[SEQ Target]]-Data[[#This Row],[SEQ Outcome]])*X14)) -> 0 | W14: =IF(AND(Data[[#This Row],[Patient Identifier]]<>"Enter ID",Data[[#This Row],[Include (Y/N)]]="Yes"),1,0) -> 0 | X14: =IF(Data[[#This Row],[SEQ Outcome]]<Data[[#This Row],[SEQ Target]],-1,1) -> 1 | Y14: BCDVA: Best corrected distance visual acuity
A15: =Data[[#This Row],[Patient Identifier]]&Data[[#This Row],[Eye (OD/OS)]] | M15: =ABS(Data[[#This Row],[Pre-Op Steep K]]-Data[[#This Row],[Pre Op Flat K]]) -> 0 | V15: =IF(X15=-1,(Data[[#This Row],[SEQ Target]]-Data[[#This Row],[SEQ Outcome]])*X15,ABS((Data[[#This Row],[SEQ Target]]-Data[[#This Row],[SEQ Outcome]])*X15)) -> 0 | W15: =IF(AND(Data[[#This Row],[Patient Identifier]]<>"Enter ID",Data[[#This Row],[Include (Y/N)]]="Yes"),1,0) -> 0 | X15: =IF(Data[[#This Row],[SEQ Outcome]]<Data[[#This Row],[SEQ Target]],-1,1) -> 1 | Y15: UCIVA: Uncorrected intermediate visual acuity
A16: =Data[[#This Row],[Patient Identifier]]&Data[[#This Row],[Eye (OD/OS)]] | M16: =ABS(Data[[#This Row],[Pre-Op Steep K]]-Data[[#This Row],[Pre Op Flat K]]) -> 0 | V16: =IF(X16=-1,(Data[[#This Row],[SEQ Target]]-Data[[#This Row],[SEQ Outcome]])*X16,ABS((Data[[#This Row],[SEQ Target]]-Data[[#This Row],[SEQ Outcome]])*X16)) -> 0 | W16: =IF(AND(Data[[#This Row],[Patient Identifier]]<>"Enter ID",Data[[#This Row],[Include (Y/N)]]="Yes"),1,0) -> 0 | X16: =IF(Data[[#This Row],[SEQ Outcome]]<Data[[#This Row],[SEQ Target]],-1,1) -> 1 | Y16: UCNVA: Uncorrected near visual acuity
A17: =Data[[#This Row],[Patient Identifier]]&Data[[#This Row],[Eye (OD/OS)]] | M17: =ABS(Data[[#This Row],[Pre-Op Steep K]]-Data[[#This Row],[Pre Op Flat K]]) -> 0 | V17: =IF(X17=-1,(Data[[#This Row],[SEQ Target]]-Data[[#This Row],[SEQ Outcome]])*X17,ABS((Data[[#This Row],[SEQ Target]]-Data[[#This Row],[SEQ Outcome]])*X17)) -> 0 | W17: =IF(AND(Data[[#This Row],[Patient Identifier]]<>"Enter ID",Data[[#This Row],[Include (Y/N)]]="Yes"),1,0) -> 0 | X17: =IF(Data[[#This Row],[SEQ Outcome]]<Data[[#This Row],[SEQ Target]],-1,1) -> 1 | Y17: Pre-Op Flat K: Pre-Operative flat corneal curvature
A18: =Data[[#This Row],[Patient Identifier]]&Data[[#This Row],[Eye (OD/OS)]] | M18: =ABS(Data[[#This Row],[Pre-Op Steep K]]-Data[[#This Row],[Pre Op Flat K]]) -> 0 | V18: =IF(X18=-1,(Data[[#This Row],[SEQ Target]]-Data[[#This Row],[SEQ Outcome]])*X18,ABS((Data[[#This Row],[SEQ Target]]-Data[[#This Row],[SEQ Outcome]])*X18)) -> 0 | W18: =IF(AND(Data[[#This Row],[Patient Identifier]]<>"Enter ID",Data[[#This Row],[Include (Y/N)]]="Yes"),1,0) -> 0 | X18: =IF(Data[[#This Row],[SEQ Outcome]]<Data[[#This Row],[SEQ Target]],-1,1) -> 1 | Y18: Pre-Op Steep K: Pre-Operative steep corneal curvature
A19: =Data[[#This Row],[Patient Identifier]]&Data[[#This Row],[Eye (OD/OS)]] | M19: =ABS(Data[[#This Row],[Pre-Op Steep K]]-Data[[#This Row],[Pre Op Flat K]]) -> 0 | V19: =IF(X19=-1,(Data[[#This Row],[SEQ Target]]-Data[[#This Row],[SEQ Outcome]])*X19,ABS((Data[[#This Row],[SEQ Target]]-Data[[#This Row],[SEQ Outcome]])*X19)) -> 0 | W19: =IF(AND(Data[[#This Row],[Patient Identifier]]<>"Enter ID",Data[[#This Row],[Include (Y/N)]]="Yes"),1,0) -> 0 | X19: =IF(Data[[#This Row],[SEQ Outcome]]<Data[[#This Row],[SEQ Target]],-1,1) -> 1 | Y19: Flat & Steep K Diff: Difference between flat K and steep K.
A20: =Data[[#This Row],[Patient Identifier]]&Data[[#This Row],[Eye (OD/OS)]] | M20: =ABS(Data[[#This Row],[Pre-Op Steep K]]-Data[[#This Row],[Pre Op Flat K]]) -> 0 | V20: =IF(X20=-1,(Data[[#This Row],[SEQ Target]]-Data[[#This Row],[SEQ Outcome]])*X20,ABS((Data[[#This Row],[SEQ Target]]-Data[[#This Row],[SEQ Outcome]])*X20)) -> 0 | W20: =IF(AND(Data[[#This Row],[Patient Identifier]]<>"Enter ID",Data[[#This Row],[Include (Y/N)]]="Yes"),1,0) -> 0 | X20: =IF(Data[[#This Row],[SEQ Outcome]]<Data[[#This Row],[SEQ Target]],-1,1) -> 1
A21: =Data[[#This Row],[Patient Identifier]]&Data[[#This Row],[Eye (OD/OS)]] | M21: =ABS(Data[[#This Row],[Pre-Op Steep K]]-Data[[#This Row],[Pre Op Flat K]]) -> 0 | V21: =IF(X21=-1,(Data[[#This Row],[SEQ Target]]-Data[[#This Row],[SEQ Outcome]])*X21,ABS((Data[[#This Row],[SEQ Target]]-Data[[#This Row],[SEQ Outcome]])*X21)) -> 0 | W21: =IF(AND(Data[[#This Row],[Patient Identifier]]<>"Enter ID",Data[[#This Row],[Include (Y/N)]]="Yes"),1,0) -> 0 | X21: =IF(Data[[#This Row],[SEQ Outcome]]<Data[[#This Row],[SEQ Target]],-1,1) -> 1
A22: =Data[[#This Row],[Patient Identifier]]&Data[[#This Row],[Eye (OD/OS)]] | M22: =ABS(Data[[#This Row],[Pre-Op Steep K]]-Data[[#This Row],[Pre Op Flat K]]) -> 0 | V22: =IF(X22=-1,(Data[[#This Row],[SEQ Target]]-Data[[#This Row],[SEQ Outcome]])*X22,ABS((Data[[#This Row],[SEQ Target]]-Data[[#This Row],[SEQ Outcome]])*X22)) -> 0 | W22: =IF(AND(Data[[#This Row],[Patient Identifier]]<>"Enter ID",Data[[#This Row],[Include (Y/N)]]="Yes"),1,0) -> 0 | X22: =IF(Data[[#This Row],[SEQ Outcome]]<Data[[#This Row],[SEQ Target]],-1,1) -> 1
A23: =Data[[#This Row],[Patient Identifier]]&Data[[#This Row],[Eye (OD/OS)]] | M23: =ABS(Data[[#This Row],[Pre-Op Steep K]]-Data[[#This Row],[Pre Op Flat K]]) -> 0 | V23: =IF(X23=-1,(Data[[#This Row],[SEQ Target]]-Data[[#This Row],[SEQ Outcome]])*X23,ABS((Data[[#This Row],[SEQ Target]]-Data[[#This Row],[SEQ Outcome]])*X23)) -> 0 | W23: =IF(AND(Data[[#This Row],[Patient Identifier]]<>"Enter ID",Data[[#This Row],[Include (Y/N)]]="Yes"),1,0) -> 0 | X23: =IF(Data[[#This Row],[SEQ Outcome]]<Data[[#This Row],[SEQ Target]],-1,1) -> 1
A24: =Data[[#This Row],[Patient Identifier]]&Data[[#This Row],[Eye (OD/OS)]] | M24: =ABS(Data[[#This Row],[Pre-Op Steep K]]-Data[[#This Row],[Pre Op Flat K]]) -> 0 | V24: =IF(X24=-1,(Data[[#This Row],[SEQ Target]]-Data[[#This Row],[SEQ Outcome]])*X24,ABS((Data[[#This Row],[SEQ Target]]-Data[[#This Row],[SEQ Outcome]])*X24)) -> 0 | W24: =IF(AND(Data[[#This Row],[Patient Identifier]]<>"Enter ID",Data[[#This Row],[Include (Y/N)]]="Yes"),1,0) -> 0 | X24: =IF(Data[[#This Row],[SEQ Outcome]]<Data[[#This Row],[SEQ Target]],-1,1) -> 1
A25: =Data[[#This Row],[Patient Identifier]]&Data[[#This Row],[Eye (OD/OS)]] | M25: =ABS(Data[[#This Row],[Pre-Op Steep K]]-Data[[#This Row],[Pre Op Flat K]]) -> 0 | V25: =IF(X25=-1,(Data[[#This Row],[SEQ Target]]-Data[[#This Row],[SEQ Outcome]])*X25,ABS((Data[[#This Row],[SEQ Target]]-Data[[#This Row],[SEQ Outcome]])*X25)) -> 0 | W25: =IF(AND(Data[[#This Row],[Patient Identifier]]<>"Enter ID",Data[[#This Row],[Include (Y/N)]]="Yes"),1,0) -> 0 | X25: =IF(Data[[#This Row],[SEQ Outcome]]<Data[[#This Row],[SEQ Target]],-1,1) -> 1
A26: =Data[[#This Row],[Patient Identifier]]&Data[[#This Row],[Eye (OD/OS)]] | M26: =ABS(Data[[#This Row],[Pre-Op Steep K]]-Data[[#This Row],[Pre Op Flat K]]) -> 0 | V26: =IF(X26=-1,(Data[[#This Row],[SEQ Target]]-Data[[#This Row],[SEQ Outcome]])*X26,ABS((Data[[#This Row],[SEQ Target]]-Data[[#This Row],[SEQ Outcome]])*X26)) -> 0 | W26: =IF(AND(Data[[#This Row],[Patient Identifier]]<>"Enter ID",Data[[#This Row],[Include (Y/N)]]="Yes"),1,0) -> 0 | X26: =IF(Data[[#This Row],[SEQ Outcome]]<Data[[#This Row],[SEQ Target]],-1,1) -> 1
A27: =Data[[#This Row],[Patient Identifier]]&Data[[#This Row],[Eye (OD/OS)]] | M27: =ABS(Data[[#This Row],[Pre-Op Steep K]]-Data[[#This Row],[Pre Op Flat K]]) -> 0 | V27: =IF(X27=-1,(Data[[#This Row],[SEQ Target]]-Data[[#This Row],[SEQ Outcome]])*X27,ABS((Data[[#This Row],[SEQ Target]]-Data[[#This Row],[SEQ Outcome]])*X27)) -> 0 | W27: =IF(AND(Data[[#This Row],[Patient Identifier]]<>"Enter ID",Data[[#This Row],[Include (Y/N)]]="Yes"),1,0) -> 0 | X27: =IF(Data[[#This Row],[SEQ Outcome]]<Data[[#This Row],[SEQ Target]],-1,1) -> 1
E28: POST OP - EVALUATION SUMMARY - OU | W28: =IFERROR(AVERAGEIFS($V$8:$V$27,$F$8:$F$27,"<>"&$W$35,$F$8:$F$27,"<>"&$W$34,$W$8:$W$27,1),0) -> 0 | Y28: Other Lenses
A29: =G29&I29 -> OU | I29: OU | W29: =IFERROR(AVERAGEIFS($V$8:$V$27,$F$8:$F$27,"<>"&$W$38,$F$8:$F$27,"<>"&$W$37,$F$8:$F$27,"<>"&$W$36,$F$8:$F$27,"<>"&$W$32,$F$8:$F$27,"<>"&$W$33,$W$8:$W$27,1),0) -> 0 | Y29: Aspire or Aspire Toric
A30: =G30&I30 -> OU | I30: OU
A31: =G31&I31 -> OU | I31: OU
A32: =G32&I32 -> OU | I32: OU | W32: enVista
A33: =G33&I33 -> OU | I33: OU | W33: enVista Toric
A34: =G34&I34 -> OU | I34: OU | W34: Aspire
A35: =G35&I35 -> OU | I35: OU | W35: Aspire Toric
A36: =G36&I36 -> OU | I36: OU | W36: IC8 - Apthera
A37: =G37&I37 -> OU | I37: OU | W37: Other B+L
A38: =G38&I38 -> OU | I38: OU | W38: Competitor

Sheet Sheet2
A1: Pre Op Flat K | B1: Pre-Op Steep K | C1: Flat & Steep K Diff | E1: Refractive Residual Cylinder | G1: Lens Type drop down menu
C2: Steep K- Flat K | G2: Apthera IOL | I2: Male
A3: 43 | B3: 44.5 | C3: 1.5 | D3: k | E3: 0.5 | F3: p | G3: enVista | I3: Female
G4: enVista Toric
G5: Alreos
G6: LI61AO
G7: Other

Sheet Envy Experience - Results
AB3: Left Eye
A4: Both Eyes | B4: =COUNTIFS('Envy Experience - Input'!U29:U38,"Yes") -> 0 | AB4: =IFERROR(VLOOKUP($X$3&"OS",'Envy Experience - Input'!$A$6:$U$27,10,0),"")
A5: Post Refractive Surgeries | B5: =COUNTIFS('Envy Experience - Input'!R8:R27,"Yes",'Envy Experience - Input'!U8:U27,"Yes") -> 0 | AB5: =IFERROR(VLOOKUP($X$3&"OS",'Envy Experience - Input'!$A$6:$U$27,11,0),"")
A6: Left Eye | B6: =COUNTIFS('Envy Experience - Input'!I8:I27,"OS",'Envy Experience - Input'!U8:U27,"Yes") -> 0 | AB6: =IFERROR(VLOOKUP($X$3&"OS",'Envy Experience - Input'!$A$6:$U$27,12,0),"")
A7: Right Eye | B7: =COUNTIFS('Envy Experience - Input'!I8:I27,"OD",'Envy Experience - Input'!U8:U27,"Yes") -> 0 | AB7: =IFERROR(VLOOKUP($X$3&"OS",'Envy Experience - Input'!$A$6:$U$27,13,0),"")
A8: =A6& " - "& B6 & " Experiences" -> Left Eye - 0 Experiences | AB8: =IFERROR(VLOOKUP($X$3&"OS",'Envy Experience - Input'!$A$6:$U$27,14,0),"")
A9: =A7& " - "& B7 & " Experiences" -> Right Eye - 0 Experiences | Z9: ="SEQ Diff Average " & TEXT($AA$11,"##0.##") -> SEQ Diff Average 0 | AA9: ='Envy Experience - Input'!W30 -> 0 | AB9: ="SEQ enVista/Toric Diff Average " & TEXT($AC$9,"##0.##") -> SEQ enVista/Toric Diff Average 0 | AC9: =AA9 -> 0
A10: =A5& " - "& B5 -> Post Refractive Surgeries - 0 | Z10: ="SEQ Diff Average " & TEXT($AA$11,"##0.##") -> SEQ Diff Average 0 | AA10: ='Envy Experience - Input'!W28 -> 0 | AB10: ="SEQ Other IOL Lens Diff Average " & TEXT($AC$10,"##0.##") -> SEQ Other IOL Lens Diff Average 0 | AC10: =AA10 -> 0
A11: BCDVA | Z11: ="SEQ Diff Average " & TEXT($AA$11,"##0.##") -> SEQ Diff Average 0 | AA11: ='Envy Experience - Input'!W29 -> 0 | AB11: ="SEQ Aspire/Aspire Toric Diff Average " & TEXT($AC$11,"##0.##") -> SEQ Aspire/Aspire Toric Diff Average 0 | AC11: ='Envy Experience - Input'!W29 -> 0
A12: Measure | B12: Right | C12: R % | D12: Left | E12: L%
A13: 20/15 | B13: =COUNTIFS('Envy Experience - Input'!$N$8:$N$27,'Envy Experience - Results'!A13,'Envy Experience - Input'!$I$8:$I$27,"OD",'Envy Experience - Input'!$U$8:$U$27,"Yes",'Envy Experience - Input'!$F$8:$F$27,"<>Aspire",'Envy Experience - Input'!$F$8:$F$27,"<>Aspire Toric") -> 0 | C13: =B13/$B$7 -> #DIV/0! | D13: =COUNTIFS('Envy Experience - Input'!$N$8:$N$27,'Envy Experience - Results'!A13,'Envy Experience - Input'!$I$8:$I$27,"OS",'Envy Experience - Input'!$U$8:$U$27,"Yes",'Envy Experience - Input'!$F$8:$F$27,"<>Aspire",'Envy Experience - Input'!$F$8:$F$27,"<>Aspire Toric") -> 0 | E13: =D13/$B$6 -> #DIV/0!
A14: 20/20 | B14: =COUNTIFS('Envy Experience - Input'!$N$8:$N$27,'Envy Experience - Results'!A14,'Envy Experience - Input'!$I$8:$I$27,"OD",'Envy Experience - Input'!$U$8:$U$27,"Yes",'Envy Experience - Input'!$F$8:$F$27,"<>Aspire",'Envy Experience - Input'!$F$8:$F$27,"<>Aspire Toric") -> 0 | C14: =B14/$B$7 -> #DIV/0! | D14: =COUNTIFS('Envy Experience - Input'!$N$8:$N$27,'Envy Experience - Results'!A14,'Envy Experience - Input'!$I$8:$I$27,"OS",'Envy Experience - Input'!$U$8:$U$27,"Yes",'Envy Experience - Input'!$F$8:$F$27,"<>Aspire",'Envy Experience - Input'!$F$8:$F$27,"<>Aspire Toric") -> 0 | E14: =D14/$B$6 -> #DIV/0!
A15: 20/25 | B15: =COUNTIFS('Envy Experience - Input'!$N$8:$N$27,'Envy Experience - Results'!A15,'Envy Experience - Input'!$I$8:$I$27,"OD",'Envy Experience - Input'!$U$8:$U$27,"Yes",'Envy Experience - Input'!$F$8:$F$27,"<>Aspire",'Envy Experience - Input'!$F$8:$F$27,"<>Aspire Toric") -> 0 | C15: =B15/$B$7 -> #DIV/0! | D15: =COUNTIFS('Envy Experience - Input'!$N$8:$N$27,'Envy Experience - Results'!A15,'Envy Experience - Input'!$I$8:$I$27,"OS",'Envy Experience - Input'!$U$8:$U$27,"Yes",'Envy Experience - Input'!$F$8:$F$27,"<>Aspire",'Envy Experience - Input'!$F$8:$F$27,"<>Aspire Toric") -> 0 | E15: =D15/$B$6 -> #DIV/0!
A16: 20/30 | B16: =COUNTIFS('Envy Experience - Input'!$N$8:$N$27,'Envy Experience - Results'!A16,'Envy Experience - Input'!$I$8:$I$27,"OD",'Envy Experience - Input'!$U$8:$U$27,"Yes",'Envy Experience - Input'!$F$8:$F$27,"<>Aspire",'Envy Experience - Input'!$F$8:$F$27,"<>Aspire Toric") -> 0 | C16: =B16/$B$7 -> #DIV/0! | D16: =COUNTIFS('Envy Experience - Input'!$N$8:$N$27,'Envy Experience - Results'!A16,'Envy Experience - Input'!$I$8:$I$27,"OS",'Envy Experience - Input'!$U$8:$U$27,"Yes",'Envy Experience - Input'!$F$8:$F$27,"<>Aspire",'Envy Experience - Input'!$F$8:$F$27,"<>Aspire Toric") -> 0 | E16: =D16/$B$6 -> #DIV/0!
A17: 20/40 | B17: =COUNTIFS('Envy Experience - Input'!$N$8:$N$27,'Envy Experience - Results'!A17,'Envy Experience - Input'!$I$8:$I$27,"OD",'Envy Experience - Input'!$U$8:$U$27,"Yes",'Envy Experience - Input'!$F$8:$F$27,"<>Aspire",'Envy Experience - Input'!$F$8:$F$27,"<>Aspire Toric") -> 0 | C17: =B17/$B$7 -> #DIV/0! | D17: =COUNTIFS('Envy Experience - Input'!$N$8:$N$27,'Envy Experience - Results'!A17,'Envy Experience - Input'!$I$8:$I$27,"OS",'Envy Experience - Input'!$U$8:$U$27,"Yes",'Envy Experience - Input'!$F$8:$F$27,"<>Aspire",'Envy Experience - Input'!$F$8:$F$27,"<>Aspire Toric") -> 0 | E17: =D17/$B$6 -> #DIV/0!
A18: 20/50 | B18: =COUNTIFS('Envy Experience - Input'!$N$8:$N$27,'Envy Experience - Results'!A18,'Envy Experience - Input'!$I$8:$I$27,"OD",'Envy Experience - Input'!$U$8:$U$27,"Yes",'Envy Experience - Input'!$F$8:$F$27,"<>Aspire",'Envy Experience - Input'!$F$8:$F$27,"<>Aspire Toric") -> 0 | C18: =B18/$B$7 -> #DIV/0! | D18: =COUNTIFS('Envy Experience - Input'!$N$8:$N$27,'Envy Experience - Results'!A18,'Envy Experience - Input'!$I$8:$I$27,"OS",'Envy Experience - Input'!$U$8:$U$27,"Yes",'Envy Experience - Input'!$F$8:$F$27,"<>Aspire",'Envy Experience - Input'!$F$8:$F$27,"<>Aspire Toric") -> 0 | E18: =D18/$B$6 -> #DIV/0!
A19: 20/60 | B19: =COUNTIFS('Envy Experience - Input'!$N$8:$N$27,'Envy Experience - Results'!A19,'Envy Experience - Input'!$I$8:$I$27,"OD",'Envy Experience - Input'!$U$8:$U$27,"Yes",'Envy Experience - Input'!$F$8:$F$27,"<>Aspire",'Envy Experience - Input'!$F$8:$F$27,"<>Aspire Toric") -> 0 | C19: =B19/$B$7 -> #DIV/0! | D19: =COUNTIFS('Envy Experience - Input'!$N$8:$N$27,'Envy Experience - Results'!A19,'Envy Experience - Input'!$I$8:$I$27,"OS",'Envy Experience - Input'!$U$8:$U$27,"Yes",'Envy Experience - Input'!$F$8:$F$27,"<>Aspire",'Envy Experience - Input'!$F$8:$F$27,"<>Aspire Toric") -> 0 | E19: =D19/$B$6 -> #DIV/0!
A20: 20/70 | B20: =COUNTIFS('Envy Experience - Input'!$N$8:$N$27,'Envy Experience - Results'!A20,'Envy Experience - Input'!$I$8:$I$27,"OD",'Envy Experience - Input'!$U$8:$U$27,"Yes",'Envy Experience - Input'!$F$8:$F$27,"<>Aspire",'Envy Experience - Input'!$F$8:$F$27,"<>Aspire Toric") -> 0 | C20: =B20/$B$7 -> #DIV/0! | D20: =COUNTIFS('Envy Experience - Input'!$N$8:$N$27,'Envy Experience - Results'!A20,'Envy Experience - Input'!$I$8:$I$27,"OS",'Envy Experience - Input'!$U$8:$U$27,"Yes",'Envy Experience - Input'!$F$8:$F$27,"<>Aspire",'Envy Experience - Input'!$F$8:$F$27,"<>Aspire Toric") -> 0 | E20: =D20/$B$6 -> #DIV/0!
B21: =SUM(B13:B20) -> 0 | C21: =SUM(C13:C20) -> #DIV/0! | D21: =SUM(D13:D20) -> 0 | E21: =SUM(E13:E20) -> #DIV/0!
A22: UCDVA
A23: Measure | B23: Right | C23: R % | D23: Left | E23: L%
A24: 20/15 | B24: =COUNTIFS('Envy Experience - Input'!$O$8:$O$27,'Envy Experience - Results'!A24,'Envy Experience - Input'!$I$8:$I$27,"OD",'Envy Experience - Input'!$U$8:$U$27,"Yes",'Envy Experience - Input'!$F$8:$F$27,"<>Aspire",'Envy Experience - Input'!$F$8:$F$27,"<>Aspire Toric") -> 0 | C24: =B24/$B$7 -> #DIV/0! | D24: =COUNTIFS('Envy Experience - Input'!$O$8:$O$27,'Envy Experience - Results'!A24,'Envy Experience - Input'!$I$8:$I$27,"OS",'Envy Experience - Input'!$U$8:$U$27,"Yes",'Envy Experience - Input'!$F$8:$F$27,"<>Aspire",'Envy Experience - Input'!$F$8:$F$27,"<>Aspire Toric") -> 0 | E24: =D24/$B$6 -> #DIV/0!
A25: 20/20 | B25: =COUNTIFS('Envy Experience - Input'!$O$8:$O$27,'Envy Experience - Results'!A25,'Envy Experience - Input'!$I$8:$I$27,"OD",'Envy Experience - Input'!$U$8:$U$27,"Yes",'Envy Experience - Input'!$F$8:$F$27,"<>Aspire",'Envy Experience - Input'!$F$8:$F$27,"<>Aspire Toric") -> 0 | C25: =B25/$B$7 -> #DIV/0! | D25: =COUNTIFS('Envy Experience - Input'!$O$8:$O$27,'Envy Experience - Results'!A25,'Envy Experience - Input'!$I$8:$I$27,"OS",'Envy Experience - Input'!$U$8:$U$27,"Yes",'Envy Experience - Input'!$F$8:$F$27,"<>Aspire",'Envy Experience - Input'!$F$8:$F$27,"<>Aspire Toric") -> 0 | E25: =D25/$B$6 -> #DIV/0!
A26: 20/25 | B26: =COUNTIFS('Envy Experience - Input'!$O$8:$O$27,'Envy Experience - Results'!A26,'Envy Experience - Input'!$I$8:$I$27,"OD",'Envy Experience - Input'!$U$8:$U$27,"Yes",'Envy Experience - Input'!$F$8:$F$27,"<>Aspire",'Envy Experience - Input'!$F$8:$F$27,"<>Aspire Toric") -> 0 | C26: =B26/$B$7 -> #DIV/0! | D26: =COUNTIFS('Envy Experience - Input'!$O$8:$O$27,'Envy Experience - Results'!A26,'Envy Experience - Input'!$I$8:$I$27,"OS",'Envy Experience - Input'!$U$8:$U$27,"Yes",'Envy Experience - Input'!$F$8:$F$27,"<>Aspire",'Envy Experience - Input'!$F$8:$F$27,"<>Aspire Toric") -> 0 | E26: =D26/$B$6 -> #DIV/0!
A27: 20/30 | B27: =COUNTIFS('Envy Experience - Input'!$O$8:$O$27,'Envy Experience - Results'!A27,'Envy Experience - Input'!$I$8:$I$27,"OD",'Envy Experience - Input'!$U$8:$U$27,"Yes",'Envy Experience - Input'!$F$8:$F$27,"<>Aspire",'Envy Experience - Input'!$F$8:$F$27,"<>Aspire Toric") -> 0 | C27: =B27/$B$7 -> #DIV/0! | D27: =COUNTIFS('Envy Experience - Input'!$O$8:$O$27,'Envy Experience - Results'!A27,'Envy Experience - Input'!$I$8:$I$27,"OS",'Envy Experience - Input'!$U$8:$U$27,"Yes",'Envy Experience - Input'!$F$8:$F$27,"<>Aspire",'Envy Experience - Input'!$F$8:$F$27,"<>Aspire Toric") -> 0 | E27: =D27/$B$6 -> #DIV/0!
A28: 20/40 | B28: =COUNTIFS('Envy Experience - Input'!$O$8:$O$27,'Envy Experience - Results'!A28,'Envy Experience - Input'!$I$8:$I$27,"OD",'Envy Experience - Input'!$U$8:$U$27,"Yes",'Envy Experience - Input'!$F$8:$F$27,"<>Aspire",'Envy Experience - Input'!$F$8:$F$27,"<>Aspire Toric") -> 0 | C28: =B28/$B$7 -> #DIV/0! | D28: =COUNTIFS('Envy Experience - Input'!$O$8:$O$27,'Envy Experience - Results'!A28,'Envy Experience - Input'!$I$8:$I$27,"OS",'Envy Experience - Input'!$U$8:$U$27,"Yes",'Envy Experience - Input'!$F$8:$F$27,"<>Aspire",'Envy Experience - Input'!$F$8:$F$27,"<>Aspire Toric") -> 0 | E28: =D28/$B$6 -> #DIV/0!
A29: 20/50 | B29: =COUNTIFS('Envy Experience - Input'!$O$8:$O$27,'Envy Experience - Results'!A29,'Envy Experience - Input'!$I$8:$I$27,"OD",'Envy Experience - Input'!$U$8:$U$27,"Yes",'Envy Experience - Input'!$F$8:$F$27,"<>Aspire",'Envy Experience - Input'!$F$8:$F$27,"<>Aspire Toric") -> 0 | C29: =B29/$B$7 -> #DIV/0! | D29: =COUNTIFS('Envy Experience - Input'!$O$8:$O$27,'Envy Experience - Results'!A29,'Envy Experience - Input'!$I$8:$I$27,"OS",'Envy Experience - Input'!$U$8:$U$27,"Yes",'Envy Experience - Input'!$F$8:$F$27,"<>Aspire",'Envy Experience - Input'!$F$8:$F$27,"<>Aspire Toric") -> 0 | E29: =D29/$B$6 -> #DIV/0!
A30: 20/60 | B30: =COUNTIFS('Envy Experience - Input'!$O$8:$O$27,'Envy Experience - Results'!A30,'Envy Experience - Input'!$I$8:$I$27,"OD",'Envy Experience - Input'!$U$8:$U$27,"Yes",'Envy Experience - Input'!$F$8:$F$27,"<>Aspire",'Envy Experience - Input'!$F$8:$F$27,"<>Aspire Toric") -> 0 | C30: =B30/$B$7 -> #DIV/0! | D30: =COUNTIFS('Envy Experience - Input'!$O$8:$O$27,'Envy Experience - Results'!A30,'Envy Experience - Input'!$I$8:$I$27,"OS",'Envy Experience - Input'!$U$8:$U$27,"Yes",'Envy Experience - Input'!$F$8:$F$27,"<>Aspire",'Envy Experience - Input'!$F$8:$F$27,"<>Aspire Toric") -> 0 | E30: =D30/$B$6 -> #DIV/0!
A31: 20/70 | B31: =COUNTIFS('Envy Experience - Input'!$O$8:$O$27,'Envy Experience - Results'!A31,'Envy Experience - Input'!$I$8:$I$27,"OD",'Envy Experience - Input'!$U$8:$U$27,"Yes",'Envy Experience - Input'!$F$8:$F$27,"<>Aspire",'Envy Experience - Input'!$F$8:$F$27,"<>Aspire Toric") -> 0 | C31: =B31/$B$7 -> #DIV/0! | D31: =COUNTIFS('Envy Experience - Input'!$O$8:$O$27,'Envy Experience - Results'!A31,'Envy Experience - Input'!$I$8:$I$27,"OS",'Envy Experience - Input'!$U$8:$U$27,"Yes",'Envy Experience - Input'!$F$8:$F$27,"<>Aspire",'Envy Experience - Input'!$F$8:$F$27,"<>Aspire Toric") -> 0 | E31: =D31/$B$6 -> #DIV/0!
B32: =SUM(B24:B31) -> 0 | C32: =SUM(C24:C31) -> #DIV/0! | D32: =SUM(D24:D31) -> 0 | E32: =SUM(E24:E31) -> #DIV/0!
A33: UCIVA
A34: Measure | B34: Right | C34: R % | D34: Left | E34: L%
A35: 20/15 | B35: =COUNTIFS('Envy Experience - Input'!$P$8:$P$27,'Envy Experience - Results'!A35,'Envy Experience - Input'!$I$8:$I$27,"OD",'Envy Experience - Input'!$U$8:$U$27,"Yes",'Envy Experience - Input'!$F$8:$F$27,"<>Aspire",'Envy Experience - Input'!$F$8:$F$27,"<>Aspire Toric") -> 0 | C35: =B35/$B$7 -> #DIV/0! | D35: =COUNTIFS('Envy Experience - Input'!$P$8:$P$27,'Envy Experience - Results'!A35,'Envy Experience - Input'!$I$8:$I$27,"OS",'Envy Experience - Input'!$U$8:$U$27,"Yes",'Envy Experience - Input'!$F$8:$F$27,"<>Aspire",'Envy Experience - Input'!$F$8:$F$27,"<>Aspire Toric") -> 0 | E35: =D35/$B$6 -> #DIV/0!
A36: 20/20 | B36: =COUNTIFS('Envy Experience - Input'!$P$8:$P$27,'Envy Experience - Results'!A36,'Envy Experience - Input'!$I$8:$I$27,"OD",'Envy Experience - Input'!$U$8:$U$27,"Yes",'Envy Experience - Input'!$F$8:$F$27,"<>Aspire",'Envy Experience - Input'!$F$8:$F$27,"<>Aspire Toric") -> 0 | C36: =B36/$B$7 -> #DIV/0! | D36: =COUNTIFS('Envy Experience - Input'!$P$8:$P$27,'Envy Experience - Results'!A36,'Envy Experience - Input'!$I$8:$I$27,"OS",'Envy Experience - Input'!$U$8:$U$27,"Yes",'Envy Experience - Input'!$F$8:$F$27,"<>Aspire",'Envy Experience - Input'!$F$8:$F$27,"<>Aspire Toric") -> 0 | E36: =D36/$B$6 -> #DIV/0!
A37: 20/25 | B37: =COUNTIFS('Envy Experience - Input'!$P$8:$P$27,'Envy Experience - Results'!A37,'Envy Experience - Input'!$I$8:$I$27,"OD",'Envy Experience - Input'!$U$8:$U$27,"Yes",'Envy Experience - Input'!$F$8:$F$27,"<>Aspire",'Envy Experience - Input'!$F$8:$F$27,"<>Aspire Toric") -> 0 | C37: =B37/$B$7 -> #DIV/0! | D37: =COUNTIFS('Envy Experience - Input'!$P$8:$P$27,'Envy Experience - Results'!A37,'Envy Experience - Input'!$I$8:$I$27,"OS",'Envy Experience - Input'!$U$8:$U$27,"Yes",'Envy Experience - Input'!$F$8:$F$27,"<>Aspire",'Envy Experience - Input'!$F$8:$F$27,"<>Aspire Toric") -> 0 | E37: =D37/$B$6 -> #DIV/0!
A38: 20/30 | B38: =COUNTIFS('Envy Experience - Input'!$P$8:$P$27,'Envy Experience - Results'!A38,'Envy Experience - Input'!$I$8:$I$27,"OD",'Envy Experience - Input'!$U$8:$U$27,"Yes",'Envy Experience - Input'!$F$8:$F$27,"<>Aspire",'Envy Experience - Input'!$F$8:$F$27,"<>Aspire Toric") -> 0 | C38: =B38/$B$7 -> #DIV/0! | D38: =COUNTIFS('Envy Experience - Input'!$P$8:$P$27,'Envy Experience - Results'!A38,'Envy Experience - Input'!$I$8:$I$27,"OS",'Envy Experience - Input'!$U$8:$U$27,"Yes",'Envy Experience - Input'!$F$8:$F$27,"<>Aspire",'Envy Experience - Input'!$F$8:$F$27,"<>Aspire Toric") -> 0 | E38: =D38/$B$6 -> #DIV/0!
A39: 20/40 | B39: =COUNTIFS('Envy Experience - Input'!$P$8:$P$27,'Envy Experience - Results'!A39,'Envy Experience - Input'!$I$8:$I$27,"OD",'Envy Experience - Input'!$U$8:$U$27,"Yes",'Envy Experience - Input'!$F$8:$F$27,"<>Aspire",'Envy Experience - Input'!$F$8:$F$27,"<>Aspire Toric") -> 0 | C39: =B39/$B$7 -> #DIV/0! | D39: =COUNTIFS('Envy Experience - Input'!$P$8:$P$27,'Envy Experience - Results'!A39,'Envy Experience - Input'!$I$8:$I$27,"OS",'Envy Experience - Input'!$U$8:$U$27,"Yes",'Envy Experience - Input'!$F$8:$F$27,"<>Aspire",'Envy Experience - Input'!$F$8:$F$27,"<>Aspire Toric") -> 0 | E39: =D39/$B$6 -> #DIV/0!
A40: 20/50 | B40: =COUNTIFS('Envy Experience - Input'!$P$8:$P$27,'Envy Experience - Results'!A40,'Envy Experience - Input'!$I$8:$I$27,"OD",'Envy Experience - Input'!$U$8:$U$27,"Yes",'Envy Experience - Input'!$F$8:$F$27,"<>Aspire",'Envy Experience - Input'!$F$8:$F$27,"<>Aspire Toric") -> 0 | C40: =B40/$B$7 -> #DIV/0! | D40: =COUNTIFS('Envy Experience - Input'!$P$8:$P$27,'Envy Experience - Results'!A40,'Envy Experience - Input'!$I$8:$I$27,"OS",'Envy Experience - Input'!$U$8:$U$27,"Yes",'Envy Experience - Input'!$F$8:$F$27,"<>Aspire",'Envy Experience - Input'!$F$8:$F$27,"<>Aspire Toric") -> 0 | E40: =D40/$B$6 -> #DIV/0!
A41: 20/60 | B41: =COUNTIFS('Envy Experience - Input'!$P$8:$P$27,'Envy Experience - Results'!A41,'Envy Experience - Input'!$I$8:$I$27,"OD",'Envy Experience - Input'!$U$8:$U$27,"Yes",'Envy Experience - Input'!$F$8:$F$27,"<>Aspire",'Envy Experience - Input'!$F$8:$F$27,"<>Aspire Toric") -> 0 | C41: =B41/$B$7 -> #DIV/0! | D41: =COUNTIFS('Envy Experience - Input'!$P$8:$P$27,'Envy Experience - Results'!A41,'Envy Experience - Input'!$I$8:$I$27,"OS",'Envy Experience - Input'!$U$8:$U$27,"Yes",'Envy Experience - Input'!$F$8:$F$27,"<>Aspire",'Envy Experience - Input'!$F$8:$F$27,"<>Aspire Toric") -> 0 | E41: =D41/$B$6 -> #DIV/0!
A42: 20/70 | B42: =COUNTIFS('Envy Experience - Input'!$P$8:$P$27,'Envy Experience - Results'!A42,'Envy Experience - Input'!$I$8:$I$27,"OD",'Envy Experience - Input'!$U$8:$U$27,"Yes",'Envy Experience - Input'!$F$8:$F$27,"<>Aspire",'Envy Experience - Input'!$F$8:$F$27,"<>Aspire Toric") -> 0 | C42: =B42/$B$7 -> #DIV/0! | D42: =COUNTIFS('Envy Experience - Input'!$P$8:$P$27,'Envy Experience - Results'!A42,'Envy Experience - Input'!$I$8:$I$27,"OS",'Envy Experience - Input'!$U$8:$U$27,"Yes",'Envy Experience - Input'!$F$8:$F$27,"<>Aspire",'Envy Experience - Input'!$F$8:$F$27,"<>Aspire Toric") -> 0 | E42: =D42/$B$6 -> #DIV/0!
...

Sheet Envy Experience Tracker 
A1: Demographics | C1: Postop week 1
A2: Preoperative | C2: Postop Month 1
A3: Operative | C3: Postop Month 3
C4: Postop Month 6
B5: Demographics | G5: Preoperative data | I5: Preoperative data | M5: Preoperative data | T5: Preoperative data | Y5: Operative data | AE5: Operative data | AI5: Operative data | AL5: Operative data | AO5: Postoperative week 1 | AS5: Postoperative week 1 | AW5: Postoperative week 1 | BA5: Postoperative week 1 | BE5: Postoperative week 1 | BJ5: Postoperative week 1 | BL5: Postoperative Month 1 | BO5: Postoperative Month 1 | BT5: Postoperative Month 1 | BW5: Postoperative Month 1 | BZ5: Postoperative Month 1 | CD5: Postoperative Month 1 | CF5: Postoperative Month 1 | CJ5: Postoperative Month 3 | CN5: Postoperative Month 3 | CT5: Postoperative Month 3 | CY5: Postoperative Month 3 | DD5: Postoperative Month 3 | DH5: Postoperative Month 6 | DL5: Postoperative Month 6 | DP5: Postoperative Month 6 | DT5: Postoperative Month 6 | DY5: Postoperative Month 6 | EB5: Postoperative Month 6
A6: Patient ID (Not to be shared) | B6: De-identified patient ID | C6: Age (years) | D6: Gender | E6: Race and ethnicity | F6: Concomitant Systemic disease | G6: Concomitant Ocular disease/Prior ocular surgery (If any) OD eye | H6: Concomitant Ocular disease/Prior ocular surgery (If any) OS eye | I6: Pre-Op Flat K OD eye | J6: Pre-Op Flat K axis OD eye | K6: Pre-Op Steep K OD eye | L6: Pre-Op Steep K axis OD eye | M6: Flat and Steep K Difference OD eye | N6: Pre-Op ALX OD eye | O6: Pre-Op ACD OD eye | P6: Pre-op LT OD eye | Q6: Pre-Op Flat K OS eye | R6: Pre-Op Flat K axis OS eye | S6: Pre-Op Steep K OS eye | T6: Pre-Op Steep K axis OS eye | U6: Flat and Steep K Difference OS eye | V6: Pre-Op ALX OS eye | W6: Pre-Op ACD OS eye | X6: Pre-op LT OS eye | Y6: Date of operative visit OD eye | Z6: IOL name OD eye | AA6: SEQ IOL Power OD eye | AD6: Toric IOL power if the implanted IOL is toric OD eye | AE6: SEQ target OD eye | AF6: Date of operative visit OS eye | AG6: IOL name OS eye | AH6: SEQ IOL Power OD eye | AI6: Toric IOL power if the implanted IOL is toric OS eye | AJ6: SEQ target OS eye | AK6: Intra-operative complications (If yes, please explain and mention the eye involved is OD/OS/both eyes) | AL6: Additional surgical procedures (If yes, please explain and mention if the procedure was done in OD/OS/both eyes) | AM6: Date of postop Week 1 visit | AN6: UDVA 20/denominator OD eye (please enter denominator only) | AO6: UDVA 20/denominator OS eye (please enter denominator only) | AP6: UDVA 20/denominator Binocular (please enter denominator only) | AQ6: CDVA 20/denominatorOD eye (please enter denominator only) | AR6: CDVA 20/denominator OS eye (please enter denominator only) | AS6: CDVA 20/denominator Binocular (please enter denominator only) | AT6: UIVA 20/denominator OD eye (please enter denominator only) | AU6: UIVA 20/denominator OS eye (please enter denominator only) | AV6: UIVA 20/denominator Binocular (please enter denominator only) | AW6: UNVA OD eye | AX6: UNVA OS eye | AY6: UNVA Binocular | AZ6: Manifest refraction sphere OD eye | BA6: Manifest refraction cylinder OD eye | BB6: Manifest refraction cylinder axis OD eye (Please enter numbers from 0 to 180 without a degree º sign) | BC6: Manifest refraction spherical equivalent OD eye | BD6: Manifest refraction sphere OS eye | BE6: Manifest refraction cylinder OS eye | BF6: Manifest refraction cylinder axis OD eye (Please enter numbers from 0 to 180 without a degree º sign) | BG6: Manifest refraction spherical equivalent OS eye | BH6: Adverse events (if yes, please list and mention the eye involved) | BI6: PCO (If yes, mention the eye and grade of PCO from 0-4) | BJ6: Glistenings (If yes, mention the eye in which it occurred and the grade of glistenings from 1-4) | BK6: Date of postop Month 1 visit | BL6: UDVA 20/denominator OD eye (please enter denominator only) | BM6: UDVA 20/denominator OS eye (please enter denominator only) | BN6: UDVA 20/denominator Binocular (please enter denominator only) | BO6: CDVA 20/denominatorOD eye (please enter denominator only) | BP6: CDVA 20/denominator OS eye (please enter denominator only) | BQ6: CDVA 20/denominator Binocular (please enter denominator only) | BR6: UIVA 20/denominator OD eye (please enter denominator only) | BS6: UIVA 20/denominator OS eye (please enter denominator only) | BT6: UIVA 20/denominator Binocular (please enter denominator only) | BU6: UNVA OD eye | BV6: UNVA OS eye | BW6: UNVA Binocular | BX6: Manifest refraction sphere OD eye | BY6: Manifest refraction cylinder OD eye | BZ6: Manifest refraction cylinder axis OD eye (Please enter numbers from 0 to 180 without a degree º sign) | CA6: Manifest refraction spherical equivalent OD eye | CB6: Manifest refraction sphere OS eye | CC6: Manifest refraction cylinder OS eye | CD6: Manifest refraction cylinder axis OD eye (Please enter numbers from 0 to 180 without a degree º sign) | CE6: Manifest refraction spherical equivalent OS eye | CF6: Adverse events (if yes, please list and mention the eye involved) | CG6: PCO (If yes, mention the eye and grade of PCO from 0-4) | CH6: Glistenings (If yes, mention the eye in which it occurred and the grade of glistenings from 1-4) | CI6: Date of postop Month 3 visit | CJ6: UDVA 20/denominator OD eye (please enter denominator only) | CK6: UDVA 20/denominator OS eye (please enter denominator only) | CL6: UDVA 20/denominator Binocular (please enter denominator only) | CM6: CDVA 20/denominator OD eye (please enter denominator only) | CN6: CDVA 20/denominator OS eye (please enter denominator only) | CO6: CDVA 20/denominator Binocular (please enter denominator only) | CP6: UIVA 20/denominator OD eye (please enter denominator only) | CQ6: UIVA 20/denominator OS eye (please enter denominator only) | CR6: UIVA 20/denominator Binocular (please enter denominator only) | CS6: UNVA OD eye | CT6: UNVA OS eye | CU6: UNVA Binocular | CV6: Manifest refraction sphere OD eye | CW6: Manifest refraction cylinder OD eye | CX6: Manifest refraction cylinder axis OD eye (Please enter numbers from 0 to 180 without a degree º sign) | CY6: Manifest refraction spherical equivalent OD eye | CZ6: Manifest refraction sphere OS eye | DA6: Manifest refraction cylinder OS eye | DB6: Manifest refraction cylinder axis OD eye (Please enter numbers from 0 to 180 without a degree º sign) | DC6: Manifest refraction spherical equivalent OS eye | DD6: Adverse events (if yes, please list and mention the eye involved) | DE6: PCO (If yes, mention the eye and grade of PCO from 0-4) | DF6: Glistenings (If yes, mention the eye in which it occurred and the grade of glistenings from 1-4) | DG6: Date of postop Month 6 visit | DH6: UDVA 20/denominator OD eye (please enter denominator only) | DI6: UDVA 20/denominator OS eye (please enter denominator only) | DJ6: UDVA 20/denominator Binocular (please enter denominator only) | DK6: CDVA 20/denominatorOD eye (please enter denominator only) | DL6: CDVA 20/denominator OS eye (please enter denominator only) | DM6: CDVA 20/denominator Binocular (please enter denominator only) | DN6: UIVA 20/denominator OD eye (please enter denominator only) | DO6: UIVA 20/denominator OS eye (please enter denominator only) | DP6: UIVA 20/denominator Binocular (please enter denominator only) | DQ6: UNVA OD eye | DR6: UNVA OS eye | DS6: UNVA Binocular | DT6: Manifest refraction sphere OD eye | DU6: Manifest refraction cylinder OD eye | DV6: Manifest refraction cylinder axis OD eye (Please enter numbers from 0 to 180 without a degree º sign) | DW6: Manifest refraction spherical equivalent OD eye | DX6: Manifest refraction sphere OS eye | DY6: Manifest refraction cylinder OS eye | DZ6: Manifest refraction cylinder axis OD eye (Please enter numbers from 0 to 180 without a degree º sign) | EA6: Manifest refraction spherical equivalent OS eye | EB6: Adverse events (if yes, please list and mention the eye involved) | EC6: PCO (If yes, mention the eye and grade of PCO from 0-4) | ED6: Glistenings (If yes, mention the eye in which it occurred and the grade of glistenings from 1-4) | EE6: Include Y/N This provides opportunity to remove outliers that would affect results, i.e. post refractive, corneal/retinal pathology or questionable outcomes noted when reviewing data
M8: =IF(OR(I8="",K8="")=TRUE,"",ABS(K8-I8)) | U8: =IF(OR(S8="",Q8="")=TRUE,"",ABS(S8-Q8)) | BC8: =IF(AND(Data4[[#This Row],[Refractive sphere OD eye]]="",Data4[[#This Row],[Refractive cylinder OD eye]]="")= TRUE,"",Data4[[#This Row],[Refractive sphere OD eye]]+(Data4[[#This Row],[Refractive cylinder OD eye]]/2)) | BG8: =IF(AND(Data4[[#This Row],[Refractive sphere OS eye]]="",Data4[[#This Row],[Refractive cylinder OS eye]]="")=TRUE,"",Data4[[#This Row],[Refractive sphere OS eye]]+(Data4[[#This Row],[Refractive cylinder OS eye]]/2)) | CA8: =IF(AND(Data4[[#This Row],[Refractive sphere OD eye14]]="",Data4[[#This Row],[Refractive cylinder OD eye15]]="")=TRUE,"",Data4[[#This Row],[Refractive sphere OD eye]]+(Data4[[#This Row],[Refractive cylinder OD eye]]/2)) | CE8: =IF(AND(Data4[[#This Row],[Refractive sphere OS eye18]]="",Data4[[#This Row],[Refractive cylinder OS eye19]]="")=TRUE,"",Data4[[#This Row],[Refractive sphere OS eye]]+(Data4[[#This Row],[Refractive cylinder OS eye]]/2)) | CY8: =IF(AND(Data4[[#This Row],[Refractive sphere OS eye19]]="",Data4[[#This Row],[Refractive cylinder OS eye20]]="")=TRUE,"",Data4[[#This Row],[Refractive sphere OD eye]]+(Data4[[#This Row],[Refractive cylinder OD eye]]/2)) | DC8: =IF(AND(Data4[[#This Row],[Refractive sphere OS eye19]]="",Data4[[#This Row],[Refractive cylinder OS eye20]]="")=TRUE,"",Data4[[#This Row],[Refractive sphere OS eye]]+(Data4[[#This Row],[Refractive cylinder OS eye]]/2)) | DW8: =IF(AND(Data4[[#This Row],[Refractive sphere OD eye1515]]="",Data4[[#This Row],[Refractive cylinder OD eye1616]]="")=TRUE,"",Data4[[#This Row],[Refractive sphere OD eye1515]]+(Data4[[#This Row],[Refractive cylinder OD eye1616]]/2)) | EA8: =IF(AND(Data4[[#This Row],[Refractive sphere OS eye1919]]="",Data4[[#This Row],[Refractive cylinder OS eye2020]]="")=TRUE,"",Data4[[#This Row],[Refractive sphere OS eye1919]]+(Data4[[#This Row],[Refractive cylinder OS eye2020]]/2))
M9: =IF(OR(I9="",K9="")=TRUE,"",ABS(K9-I9)) | U9: =IF(OR(S9="",Q9="")=TRUE,"",ABS(S9-Q9)) | BC9: =IF(AND(Data4[[#This Row],[Refractive sphere OD eye]]="",Data4[[#This Row],[Refractive cylinder OD eye]]="")= TRUE,"",Data4[[#This Row],[Refractive sphere OD eye]]+(Data4[[#This Row],[Refractive cylinder OD eye]]/2)) | BG9: =IF(AND(Data4[[#This Row],[Refractive sphere OS eye]]="",Data4[[#This Row],[Refractive cylinder OS eye]]="")=TRUE,"",Data4[[#This Row],[Refractive sphere OS eye]]+(Data4[[#This Row],[Refractive cylinder OS eye]]/2)) | CA9: =IF(AND(Data4[[#This Row],[Refractive sphere OD eye14]]="",Data4[[#This Row],[Refractive cylinder OD eye15]]="")=TRUE,"",Data4[[#This Row],[Refractive sphere OD eye]]+(Data4[[#This Row],[Refractive cylinder OD eye]]/2)) | CE9: =IF(AND(Data4[[#This Row],[Refractive sphere OS eye18]]="",Data4[[#This Row],[Refractive cylinder OS eye19]]="")=TRUE,"",Data4[[#This Row],[Refractive sphere OS eye]]+(Data4[[#This Row],[Refractive cylinder OS eye]]/2)) | CY9: =IF(AND(Data4[[#This Row],[Refractive sphere OS eye19]]="",Data4[[#This Row],[Refractive cylinder OS eye20]]="")=TRUE,"",Data4[[#This Row],[Refractive sphere OD eye]]+(Data4[[#This Row],[Refractive cylinder OD eye]]/2)) | DC9: =IF(AND(Data4[[#This Row],[Refractive sphere OS eye19]]="",Data4[[#This Row],[Refractive cylinder OS eye20]]="")=TRUE,"",Data4[[#This Row],[Refractive sphere OS eye]]+(Data4[[#This Row],[Refractive cylinder OS eye]]/2)) | DW9: =IF(AND(Data4[[#This Row],[Refractive sphere OD eye1515]]="",Data4[[#This Row],[Refractive cylinder OD eye1616]]="")=TRUE,"",Data4[[#This Row],[Refractive sphere OD eye1515]]+(Data4[[#This Row],[Refractive cylinder OD eye1616]]/2)) | EA9: =IF(AND(Data4[[#This Row],[Refractive sphere OS eye1919]]="",Data4[[#This Row],[Refractive cylinder OS eye2020]]="")=TRUE,"",Data4[[#This Row],[Refractive sphere OS eye1919]]+(Data4[[#This Row],[Refractive cylinder OS eye2020]]/2))
M10: =IF(OR(I10="",K10="")=TRUE,"",ABS(K10-I10)) | U10: =IF(OR(S10="",Q10="")=TRUE,"",ABS(S10-Q10)) | BC10: =IF(AND(Data4[[#This Row],[Refractive sphere OD eye]]="",Data4[[#This Row],[Refractive cylinder OD eye]]="")= TRUE,"",Data4[[#This Row],[Refractive sphere OD eye]]+(Data4[[#This Row],[Refractive cylinder OD eye]]/2)) | BG10: =IF(AND(Data4[[#This Row],[Refractive sphere OS eye]]="",Data4[[#This Row],[Refractive cylinder OS eye]]="")=TRUE,"",Data4[[#This Row],[Refractive sphere OS eye]]+(Data4[[#This Row],[Refractive cylinder OS eye]]/2)) | CA10: =IF(AND(Data4[[#This Row],[Refractive sphere OD eye14]]="",Data4[[#This Row],[Refractive cylinder OD eye15]]="")=TRUE,"",Data4[[#This Row],[Refractive sphere OD eye]]+(Data4[[#This Row],[Refractive cylinder OD eye]]/2)) | CE10: =IF(AND(Data4[[#This Row],[Refractive sphere OS eye18]]="",Data4[[#This Row],[Refractive cylinder OS eye19]]="")=TRUE,"",Data4[[#This Row],[Refractive sphere OS eye]]+(Data4[[#This Row],[Refractive cylinder OS eye]]/2)) | CY10: =IF(AND(Data4[[#This Row],[Refractive sphere OS eye19]]="",Data4[[#This Row],[Refractive cylinder OS eye20]]="")=TRUE,"",Data4[[#This Row],[Refractive sphere OD eye]]+(Data4[[#This Row],[Refractive cylinder OD eye]]/2)) | DC10: =IF(AND(Data4[[#This Row],[Refractive sphere OS eye19]]="",Data4[[#This Row],[Refractive cylinder OS eye20]]="")=TRUE,"",Data4[[#This Row],[Refractive sphere OS eye]]+(Data4[[#This Row],[Refractive cylinder OS eye]]/2)) | DW10: =IF(AND(Data4[[#This Row],[Refractive sphere OD eye1515]]="",Data4[[#This Row],[Refractive cylinder OD eye1616]]="")=TRUE,"",Data4[[#This Row],[Refractive sphere OD eye1515]]+(Data4[[#This Row],[Refractive cylinder OD eye1616]]/2)) | EA10: =IF(AND(Data4[[#This Row],[Refractive sphere OS eye1919]]="",Data4[[#This Row],[Refractive cylinder OS eye2020]]="")=TRUE,"",Data4[[#This Row],[Refractive sphere OS eye1919]]+(Data4[[#This Row],[Refractive cylinder OS eye2020]]/2))
M11: =IF(OR(I11="",K11="")=TRUE,"",ABS(K11-I11)) | U11: =IF(OR(S11="",Q11="")=TRUE,"",ABS(S11-Q11)) | BC11: =IF(AND(Data4[[#This Row],[Refractive sphere OD eye]]="",Data4[[#This Row],[Refractive cylinder OD eye]]="")= TRUE,"",Data4[[#This Row],[Refractive sphere OD eye]]+(Data4[[#This Row],[Refractive cylinder OD eye]]/2)) | BG11: =IF(AND(Data4[[#This Row],[Refractive sphere OS eye]]="",Data4[[#This Row],[Refractive cylinder OS eye]]="")=TRUE,"",Data4[[#This Row],[Refractive sphere OS eye]]+(Data4[[#This Row],[Refractive cylinder OS eye]]/2)) | CA11: =IF(AND(Data4[[#This Row],[Refractive sphere OD eye14]]="",Data4[[#This Row],[Refractive cylinder OD eye15]]="")=TRUE,"",Data4[[#This Row],[Refractive sphere OD eye]]+(Data4[[#This Row],[Refractive cylinder OD eye]]/2)) | CE11: =IF(AND(Data4[[#This Row],[Refractive sphere OS eye18]]="",Data4[[#This Row],[Refractive cylinder OS eye19]]="")=TRUE,"",Data4[[#This Row],[Refractive sphere OS eye]]+(Data4[[#This Row],[Refractive cylinder OS eye]]/2)) | CY11: =IF(AND(Data4[[#This Row],[Refractive sphere OS eye19]]="",Data4[[#This Row],[Refractive cylinder OS eye20]]="")=TRUE,"",Data4[[#This Row],[Refractive sphere OD eye]]+(Data4[[#This Row],[Refractive cylinder OD eye]]/2)) | DC11: =IF(AND(Data4[[#This Row],[Refractive sphere OS eye19]]="",Data4[[#This Row],[Refractive cylinder OS eye20]]="")=TRUE,"",Data4[[#This Row],[Refractive sphere OS eye]]+(Data4[[#This Row],[Refractive cylinder OS eye]]/2)) | DW11: =IF(AND(Data4[[#This Row],[Refractive sphere OD eye1515]]="",Data4[[#This Row],[Refractive cylinder OD eye1616]]="")=TRUE,"",Data4[[#This Row],[Refractive sphere OD eye1515]]+(Data4[[#This Row],[Refractive cylinder OD eye1616]]/2)) | EA11: =IF(AND(Data4[[#This Row],[Refractive sphere OS eye1919]]="",Data4[[#This Row],[Refractive cylinder OS eye2020]]="")=TRUE,"",Data4[[#This Row],[Refractive sphere OS eye1919]]+(Data4[[#This Row],[Refractive cylinder OS eye2020]]/2))
M12: =IF(OR(I12="",K12="")=TRUE,"",ABS(K12-I12)) | U12: =IF(OR(S12="",Q12="")=TRUE,"",ABS(S12-Q12)) | BC12: =IF(AND(Data4[[#This Row],[Refractive sphere OD eye]]="",Data4[[#This Row],[Refractive cylinder OD eye]]="")= TRUE,"",Data4[[#This Row],[Refractive sphere OD eye]]+(Data4[[#This Row],[Refractive cylinder OD eye]]/2)) | BG12: =IF(AND(Data4[[#This Row],[Refractive sphere OS eye]]="",Data4[[#This Row],[Refractive cylinder OS eye]]="")=TRUE,"",Data4[[#This Row],[Refractive sphere OS eye]]+(Data4[[#This Row],[Refractive cylinder OS eye]]/2)) | CA12: =IF(AND(Data4[[#This Row],[Refractive sphere OD eye14]]="",Data4[[#This Row],[Refractive cylinder OD eye15]]="")=TRUE,"",Data4[[#This Row],[Refractive sphere OD eye]]+(Data4[[#This Row],[Refractive cylinder OD eye]]/2)) | CE12: =IF(AND(Data4[[#This Row],[Refractive sphere OS eye18]]="",Data4[[#This Row],[Refractive cylinder OS eye19]]="")=TRUE,"",Data4[[#This Row],[Refractive sphere OS eye]]+(Data4[[#This Row],[Refractive cylinder OS eye]]/2)) | CY12: =IF(AND(Data4[[#This Row],[Refractive sphere OS eye19]]="",Data4[[#This Row],[Refractive cylinder OS eye20]]="")=TRUE,"",Data4[[#This Row],[Refractive sphere OD eye]]+(Data4[[#This Row],[Refractive cylinder OD eye]]/2)) | DC12: =IF(AND(Data4[[#This Row],[Refractive sphere OS eye19]]="",Data4[[#This Row],[Refractive cylinder OS eye20]]="")=TRUE,"",Data4[[#This Row],[Refractive sphere OS eye]]+(Data4[[#This Row],[Refractive cylinder OS eye]]/2)) | DW12: =IF(AND(Data4[[#This Row],[Refractive sphere OD eye1515]]="",Data4[[#This Row],[Refractive cylinder OD eye1616]]="")=TRUE,"",Data4[[#This Row],[Refractive sphere OD eye1515]]+(Data4[[#This Row],[Refractive cylinder OD eye1616]]/2)) | EA12: =IF(AND(Data4[[#This Row],[Refractive sphere OS eye1919]]="",Data4[[#This Row],[Refractive cylinder OS eye2020]]="")=TRUE,"",Data4[[#This Row],[Refractive sphere OS eye1919]]+(Data4[[#This Row],[Refractive cylinder OS eye2020]]/2))
M13: =IF(OR(I13="",K13="")=TRUE,"",ABS(K13-I13)) | U13: =IF(OR(S13="",Q13="")=TRUE,"",ABS(S13-Q13)) | BC13: =IF(AND(Data4[[#This Row],[Refractive sphere OD eye]]="",Data4[[#This Row],[Refractive cylinder OD eye]]="")= TRUE,"",Data4[[#This Row],[Refractive sphere OD eye]]+(Data4[[#This Row],[Refractive cylinder OD eye]]/2)) | BG13: =IF(AND(Data4[[#This Row],[Refractive sphere OS eye]]="",Data4[[#This Row],[Refractive cylinder OS eye]]="")=TRUE,"",Data4[[#This Row],[Refractive sphere OS eye]]+(Data4[[#This Row],[Refractive cylinder OS eye]]/2)) | CA13: =IF(AND(Data4[[#This Row],[Refractive sphere OD eye14]]="",Data4[[#This Row],[Refractive cylinder OD eye15]]="")=TRUE,"",Data4[[#This Row],[Refractive sphere OD eye]]+(Data4[[#This Row],[Refractive cylinder OD eye]]/2)) | CE13: =IF(AND(Data4[[#This Row],[Refractive sphere OS eye18]]="",Data4[[#This Row],[Refractive cylinder OS eye19]]="")=TRUE,"",Data4[[#This Row],[Refractive sphere OS eye]]+(Data4[[#This Row],[Refractive cylinder OS eye]]/2)) | CY13: =IF(AND(Data4[[#This Row],[Refractive sphere OS eye19]]="",Data4[[#This Row],[Refractive cylinder OS eye20]]="")=TRUE,"",Data4[[#This Row],[Refractive sphere OD eye]]+(Data4[[#This Row],[Refractive cylinder OD eye]]/2)) | DC13: =IF(AND(Data4[[#This Row],[Refractive sphere OS eye19]]="",Data4[[#This Row],[Refractive cylinder OS eye20]]="")=TRUE,"",Data4[[#This Row],[Refractive sphere OS eye]]+(Data4[[#This Row],[Refractive cylinder OS eye]]/2)) | DW13: =IF(AND(Data4[[#This Row],[Refractive sphere OD eye1515]]="",Data4[[#This Row],[Refractive cylinder OD eye1616]]="")=TRUE,"",Data4[[#This Row],[Refractive sphere OD eye1515]]+(Data4[[#This Row],[Refractive cylinder OD eye1616]]/2)) | EA13: =IF(AND(Data4[[#This Row],[Refractive sphere OS eye1919]]="",Data4[[#This Row],[Refractive cylinder OS eye2020]]="")=TRUE,"",Data4[[#This Row],[Refractive sphere OS eye1919]]+(Data4[[#This Row],[Refractive cylinder OS eye2020]]/2))
M14: =IF(OR(I14="",K14="")=TRUE,"",ABS(K14-I14)) | U14: =IF(OR(S14="",Q14="")=TRUE,"",ABS(S14-Q14)) | BC14: =IF(AND(Data4[[#This Row],[Refractive sphere OD eye]]="",Data4[[#This Row],[Refractive cylinder OD eye]]="")= TRUE,"",Data4[[#This Row],[Refractive sphere OD eye]]+(Data4[[#This Row],[Refractive cylinder OD eye]]/2)) | BG14: =IF(AND(Data4[[#This Row],[Refractive sphere OS eye]]="",Data4[[#This Row],[Refractive cylinder OS eye]]="")=TRUE,"",Data4[[#This Row],[Refractive sphere OS eye]]+(Data4[[#This Row],[Refractive cylinder OS eye]]/2)) | CA14: =IF(AND(Data4[[#This Row],[Refractive sphere OD eye14]]="",Data4[[#This Row],[Refractive cylinder OD eye15]]="")=TRUE,"",Data4[[#This Row],[Refractive sphere OD eye]]+(Data4[[#This Row],[Refractive cylinder OD eye]]/2)) | CE14: =IF(AND(Data4[[#This Row],[Refractive sphere OS eye18]]="",Data4[[#This Row],[Refractive cylinder OS eye19]]="")=TRUE,"",Data4[[#This Row],[Refractive sphere OS eye]]+(Data4[[#This Row],[Refractive cylinder OS eye]]/2)) | CY14: =IF(AND(Data4[[#This Row],[Refractive sphere OS eye19]]="",Data4[[#This Row],[Refractive cylinder OS eye20]]="")=TRUE,"",Data4[[#This Row],[Refractive sphere OD eye]]+(Data4[[#This Row],[Refractive cylinder OD eye]]/2)) | DC14: =IF(AND(Data4[[#This Row],[Refractive sphere OS eye19]]="",Data4[[#This Row],[Refractive cylinder OS eye20]]="")=TRUE,"",Data4[[#This Row],[Refractive sphere OS eye]]+(Data4[[#This Row],[Refractive cylinder OS eye]]/2)) | DW14: =IF(AND(Data4[[#This Row],[Refractive sphere OD eye1515]]="",Data4[[#This Row],[Refractive cylinder OD eye1616]]="")=TRUE,"",Data4[[#This Row],[Refractive sphere OD eye1515]]+(Data4[[#This Row],[Refractive cylinder OD eye1616]]/2)) | EA14: =IF(AND(Data4[[#This Row],[Refractive sphere OS eye1919]]="",Data4[[#This Row],[Refractive cylinder OS eye2020]]="")=TRUE,"",Data4[[#This Row],[Refractive sphere OS eye1919]]+(Data4[[#This Row],[Refractive cylinder OS eye2020]]/2))
M15: =IF(OR(I15="",K15="")=TRUE,"",ABS(K15-I15)) | U15: =IF(OR(S15="",Q15="")=TRUE,"",ABS(S15-Q15)) | BC15: =IF(AND(Data4[[#This Row],[Refractive sphere OD eye]]="",Data4[[#This Row],[Refractive cylinder OD eye]]="")= TRUE,"",Data4[[#This Row],[Refractive sphere OD eye]]+(Data4[[#This Row],[Refractive cylinder OD eye]]/2)) | BG15: =IF(AND(Data4[[#This Row],[Refractive sphere OS eye]]="",Data4[[#This Row],[Refractive cylinder OS eye]]="")=TRUE,"",Data4[[#This Row],[Refractive sphere OS eye]]+(Data4[[#This Row],[Refractive cylinder OS eye]]/2)) | CA15: =IF(AND(Data4[[#This Row],[Refractive sphere OD eye14]]="",Data4[[#This Row],[Refractive cylinder OD eye15]]="")=TRUE,"",Data4[[#This Row],[Refractive sphere OD eye]]+(Data4[[#This Row],[Refractive cylinder OD eye]]/2)) | CE15: =IF(AND(Data4[[#This Row],[Refractive sphere OS eye18]]="",Data4[[#This Row],[Refractive cylinder OS eye19]]="")=TRUE,"",Data4[[#This Row],[Refractive sphere OS eye]]+(Data4[[#This Row],[Refractive cylinder OS eye]]/2)) | CY15: =IF(AND(Data4[[#This Row],[Refractive sphere OS eye19]]="",Data4[[#This Row],[Refractive cylinder OS eye20]]="")=TRUE,"",Data4[[#This Row],[Refractive sphere OD eye]]+(Data4[[#This Row],[Refractive cylinder OD eye]]/2)) | DC15: =IF(AND(Data4[[#This Row],[Refractive sphere OS eye19]]="",Data4[[#This Row],[Refractive cylinder OS eye20]]="")=TRUE,"",Data4[[#This Row],[Refractive sphere OS eye]]+(Data4[[#This Row],[Refractive cylinder OS eye]]/2)) | DW15: =IF(AND(Data4[[#This Row],[Refractive sphere OD eye1515]]="",Data4[[#This Row],[Refractive cylinder OD eye1616]]="")=TRUE,"",Data4[[#This Row],[Refractive sphere OD eye1515]]+(Data4[[#This Row],[Refractive cylinder OD eye1616]]/2)) | EA15: =IF(AND(Data4[[#This Row],[Refractive sphere OS eye1919]]="",Data4[[#This Row],[Refractive cylinder OS eye2020]]="")=TRUE,"",Data4[[#This Row],[Refractive sphere OS eye1919]]+(Data4[[#This Row],[Refractive cylinder OS eye2020]]/2))
M16: =IF(OR(I16="",K16="")=TRUE,"",ABS(K16-I16)) | U16: =IF(OR(S16="",Q16="")=TRUE,"",ABS(S16-Q16)) | BC16: =IF(AND(Data4[[#This Row],[Refractive sphere OD eye]]="",Data4[[#This Row],[Refractive cylinder OD eye]]="")= TRUE,"",Data4[[#This Row],[Refractive sphere OD eye]]+(Data4[[#This Row],[Refractive cylinder OD eye]]/2)) | BG16: =IF(AND(Data4[[#This Row],[Refractive sphere OS eye]]="",Data4[[#This Row],[Refractive cylinder OS eye]]="")=TRUE,"",Data4[[#This Row],[Refractive sphere OS eye]]+(Data4[[#This Row],[Refractive cylinder OS eye]]/2)) | CA16: =IF(AND(Data4[[#This Row],[Refractive sphere OD eye14]]="",Data4[[#This Row],[Refractive cylinder OD eye15]]="")=TRUE,"",Data4[[#This Row],[Refractive sphere OD eye]]+(Data4[[#This Row],[Refractive cylinder OD eye]]/2)) | CE16: =IF(AND(Data4[[#This Row],[Refractive sphere OS eye18]]="",Data4[[#This Row],[Refractive cylinder OS eye19]]="")=TRUE,"",Data4[[#This Row],[Refractive sphere OS eye]]+(Data4[[#This Row],[Refractive cylinder OS eye]]/2)) | CY16: =IF(AND(Data4[[#This Row],[Refractive sphere OS eye19]]="",Data4[[#This Row],[Refractive cylinder OS eye20]]="")=TRUE,"",Data4[[#This Row],[Refractive sphere OD eye]]+(Data4[[#This Row],[Refractive cylinder OD eye]]/2)) | DC16: =IF(AND(Data4[[#This Row],[Refractive sphere OS eye19]]="",Data4[[#This Row],[Refractive cylinder OS eye20]]="")=TRUE,"",Data4[[#This Row],[Refractive sphere OS eye]]+(Data4[[#This Row],[Refractive cylinder OS eye]]/2)) | DW16: =IF(AND(Data4[[#This Row],[Refractive sphere OD eye1515]]="",Data4[[#This Row],[Refractive cylinder OD eye1616]]="")=TRUE,"",Data4[[#This Row],[Refractive sphere OD eye1515]]+(Data4[[#This Row],[Refractive cylinder OD eye1616]]/2)) | EA16: =IF(AND(Data4[[#This Row],[Refractive sphere OS eye1919]]="",Data4[[#This Row],[Refractive cylinder OS eye2020]]="")=TRUE,"",Data4[[#This Row],[Refractive sphere OS eye1919]]+(Data4[[#This Row],[Refractive cylinder OS eye2020]]/2))
M17: =IF(OR(I17="",K17="")=TRUE,"",ABS(K17-I17)) | U17: =IF(OR(S17="",Q17="")=TRUE,"",ABS(S17-Q17)) | BC17: =IF(AND(Data4[[#This Row],[Refractive sphere OD eye]]="",Data4[[#This Row],[Refractive cylinder OD eye]]="")= TRUE,"",Data4[[#This Row],[Refractive sphere OD eye]]+(Data4[[#This Row],[Refractive cylinder OD eye]]/2)) | BG17: =IF(AND(Data4[[#This Row],[Refractive sphere OS eye]]="",Data4[[#This Row],[Refractive cylinder OS eye]]="")=TRUE,"",Data4[[#This Row],[Refractive sphere OS eye]]+(Data4[[#This Row],[Refractive cylinder OS eye]]/2)) | CA17: =IF(AND(Data4[[#This Row],[Refractive sphere OD eye14]]="",Data4[[#This Row],[Refractive cylinder OD eye15]]="")=TRUE,"",Data4[[#This Row],[Refractive sphere OD eye]]+(Data4[[#This Row],[Refractive cylinder OD eye]]/2)) | CE17: =IF(AND(Data4[[#This Row],[Refractive sphere OS eye18]]="",Data4[[#This Row],[Refractive cylinder OS eye19]]="")=TRUE,"",Data4[[#This Row],[Refractive sphere OS eye]]+(Data4[[#This Row],[Refractive cylinder OS eye]]/2)) | CY17: =IF(AND(Data4[[#This Row],[Refractive sphere OS eye19]]="",Data4[[#This Row],[Refractive cylinder OS eye20]]="")=TRUE,"",Data4[[#This Row],[Refractive sphere OD eye]]+(Data4[[#This Row],[Refractive cylinder OD eye]]/2)) | DC17: =IF(AND(Data4[[#This Row],[Refractive sphere OS eye19]]="",Data4[[#This Row],[Refractive cylinder OS eye20]]="")=TRUE,"",Data4[[#This Row],[Refractive sphere OS eye]]+(Data4[[#This Row],[Refractive cylinder OS eye]]/2)) | DW17: =IF(AND(Data4[[#This Row],[Refractive sphere OD eye1515]]="",Data4[[#This Row],[Refractive cylinder OD eye1616]]="")=TRUE,"",Data4[[#This Row],[Refractive sphere OD eye1515]]+(Data4[[#This Row],[Refractive cylinder OD eye1616]]/2)) | EA17: =IF(AND(Data4[[#This Row],[Refractive sphere OS eye1919]]="",Data4[[#This Row],[Refractive cylinder OS eye2020]]="")=TRUE,"",Data4[[#This Row],[Refractive sphere OS eye1919]]+(Data4[[#This Row],[Refractive cylinder OS eye2020]]/2))
